<?xml version="1.0" ?>
<robot name="rover" xmlns:xacro="http://www.ros.org/wiki/xacro">
  <material name="black">
    <color rgba="0.0 0.0 0.0 1.0"/>
  </material>
  <material name="blue">
    <color rgba="0.203125 0.23828125 0.28515625 1.0"/>
  </material>
  <material name="green">
    <color rgba="0.0 0.8 0.0 1.0"/>
  </material>
  <material name="grey">
    <color rgba="0.2 0.2 0.2 1.0"/>
  </material>
  <material name="orange">
    <color rgba="1.0 0.423529411765 0.0392156862745 1.0"/>
  </material>
  <material name="brown">
    <color rgba="0.870588235294 0.811764705882 0.764705882353 1.0"/>
  </material>
  <material name="red">
    <color rgba="0.80078125 0.12890625 0.1328125 1.0"/>
  </material>
  <material name="white">
    <color rgba="1.0 1.0 1.0 1.0"/>
  </material>
  
  <gazebo reference="link_chassis">
    <material>Gazebo/Orange</material>
  </gazebo>
  <gazebo reference="link_back_left_wheel">
    <material>Gazebo/Blue</material>
  </gazebo>
  <gazebo reference="link_back_right_wheel">
    <material>Gazebo/Blue</material>
  </gazebo>
  <gazebo reference="link_front_left_wheel">
    <material>Gazebo/Blue</material>
  </gazebo>
  <gazebo reference="link_front_right_wheel">
    <material>Gazebo/Blue</material>
  </gazebo>
  <gazebo reference="link_front_left_hinge">
    <material>Gazebo/Orange</material>
  </gazebo>
  <gazebo reference="link_front_right_hinge">
    <material>Gazebo/Orange</material>
  </gazebo>
  <gazebo reference="camera_link">
    <material>Gazebo/Black</material>
	</gazebo>

  <!-- camera -->
  <gazebo reference="camera_link">
    <sensor type="camera" name="main_cam">
      <update_rate>30.0</update_rate>
      <camera name="head">
        <horizontal_fov>1.777778</horizontal_fov>
        <image>
          <width>960</width>
          <height>616</height>
          <format>R8G8B8</format>
        </image>
        <clip>
          <near>0.02</near>
          <far>300</far>
        </clip>
        <noise>
          <type>gaussian</type>
          <!-- Noise is sampled independently per pixel on each frame.
               That pixel's noise value is added to each of its color
               channels, which at that point lie in the range [0,1]. -->
          <mean>0.0</mean>
          <stddev>0.007</stddev>
        </noise>
      </camera>
      <plugin name="camera_controller" filename="libgazebo_ros_camera.so">
        <alwaysOn>true</alwaysOn>
        <updateRate>60.0</updateRate>
        <cameraName>camera1</cameraName>
        <imageTopicName>image_raw</imageTopicName>
        <cameraInfoTopicName>camera_info</cameraInfoTopicName>
        <frameName>camera_link</frameName>
        <hackBaseline>0.07</hackBaseline>
        <distortionK1>0.0</distortionK1>
        <distortionK2>0.0</distortionK2>
        <distortionK3>0.0</distortionK3>
        <distortionT1>0.0</distortionT1>
        <distortionT2>0.0</distortionT2>
      </plugin>
    </sensor>
  </gazebo>
  
<!--imu plugin-->
<gazebo reference="imu_link">
<gravity>true</gravity>
<sensor name="imu_sensor" type="imu">
<always_on>true</always_on>
<update_rate>100</update_rate>
<visualize>true</visualize>
<topic>__default_topic__</topic>
<plugin filename="libgazebo_ros_imu_sensor.so" name="imu_plugin">
<topicName>imu</topicName>
<bodyName>imu_link</bodyName>
<updateRateHZ>10.0</updateRateHZ>
<gaussianNoise>0.0</gaussianNoise>
<xyzOffset>0 0 0</xyzOffset>
<rpyOffset>0 0 0</rpyOffset>
<frameName>imu_link</frameName>
<initialOrientationAsReference>false</initialOrientationAsReference>
</plugin>
<pose>0 0 0 0 0 0</pose>
</sensor>
</gazebo>

  <!-- chassis -->
  <link name="link_chassis">
    <!-- pose and inertial -->
    <pose>0 0 0 0 0 0</pose>
    <inertial>
      <mass value="0.796"/>
      <origin rpy="0 0 0" xyz="0 0 0"/>
      <inertia ixx="0.001573" ixy="0" ixz="0" iyy="0.004227" iyz="0" izz="0.005638"/>
    </inertial>
    <!-- body -->
    <collision name="collision_chassis">
      <geometry>
        <box size="0.25 0.15 0.035"/>
      </geometry>
    </collision>
    <visual>
      <origin rpy="0 0 0" xyz="0 0 0"/>
      <geometry>
        <box size="0.25 0.15 0.035"/>
      </geometry>
      <material name="blue"/>
    </visual>
  </link> 

<!-- wheels & hinges -->

<!-- Front right -->
  <link name="link_front_right_wheel">
    <inertial>
      <mass value="0.049"/>
      <origin rpy="0 1.5707 1.5707" xyz="0 0 0"/>
      <inertia ixx="1.755e-5" ixy="0" ixz="0" iyy="1.755e-5" iyz="0" izz="3.001e-5"/> 
    </inertial>
    <collision name="link_front_right_wheel_collision">
      <origin rpy="0  -1.5707  -1.5707" xyz="0 0 0"/>
      <geometry>
        <cylinder length="0.025" radius="0.035"/>
      </geometry>
    </collision>
    <visual name="link_front_right_wheel_visual">
      <origin rpy="0  -1.5707  -1.5707" xyz="0 0 0"/>
      <geometry>
        <cylinder length="0.025" radius="0.035"/>
      </geometry>
    </visual>
  </link>
  
  <link name="link_front_right_hinge">
    <inertial>
      <mass value="1e-5"/>
      <origin rpy="0 0 0" xyz="0 0 0"/>
      <inertia ixx="1e-6" ixy="0" ixz="0" iyy="1e-6" iyz="0" izz="1e-6"/>
    </inertial>
  </link>


  <joint name="joint_front_right_wheel" type="continuous">
    <origin rpy="0 0 0" xyz="0 -0.015 0"/>
    <child link="link_front_right_wheel"/>
    <parent link="link_front_right_hinge"/>
    <axis rpy="0 0 0" xyz="0 1 0"/>
    <limit effort="5" velocity="10"/>
    <joint_properties damping="0.0" friction="0.0"/>
  </joint>


 <joint name="joint_front_right_hinge" type="revolute">
    <origin rpy="0 0 0" xyz="0.125 -0.085 0.0"/>
    <child link="link_front_right_hinge"/>
    <parent link="link_chassis"/>
    <axis rpy="0 0 0" xyz="0 0 1"/>
    <limit  effort="10" velocity="5" lower="-0.261" upper="0.174"/>
    <joint_properties damping="0.0" friction="0.0"/>
  </joint>

<!-- front left -->

  <link name="link_front_left_wheel">
    <inertial>
      <mass value="0.049"/>
      <origin rpy="0 1.5707 1.5707" xyz="0 0 0"/>
      <inertia ixx="1.755e-5" ixy="0" ixz="0" iyy="1.755e-5" iyz="0" izz="3.001e-5"/>
    </inertial>
    <collision name="link_front_left_wheel_collision">
      <origin rpy="0 1.5707 1.5707" xyz="0 0 0"/>
      <geometry>
        <cylinder length="0.025" radius="0.035"/>
      </geometry>
    </collision>
    <visual name="link_front_left_wheel_visual">
      <origin rpy="0 1.5707 1.5707" xyz="0 0 0"/>
      <geometry>
        <cylinder length="0.025" radius="0.035"/>
      </geometry>
    </visual>
  </link>

  <link name="link_front_left_hinge">
    <inertial>
      <mass value="1e-5"/>
      <origin rpy="0 0 0" xyz="0 0 0"/>
      <inertia ixx="1e-6" ixy="0" ixz="0" iyy="1e-6" iyz="0" izz="1e-6"/>
    </inertial>
  </link>
  
  <joint name="joint_front_left_wheel" type="continuous">
    <origin rpy="0 0 0" xyz="0.0 0.015 0.0"/>
    <child link="link_front_left_wheel"/>
    <parent link="link_front_left_hinge"/>
    <axis rpy="0 0 0" xyz="0 1 0"/>
    <limit effort="5" velocity="10"/>
    <joint_properties damping="0.0" friction="0.0"/>
  </joint>

  <joint name="joint_front_left_hinge" type="revolute">
    <origin rpy="0 0 0" xyz="0.125 0.085 0.0"/>
    <child link="link_front_left_hinge"/>
    <parent link="link_chassis"/>
    <axis rpy="0 0 0" xyz="0 0 1"/>
    <limit effort="10" velocity="5" lower= "-0.261" upper="0.174"/>
    <joint_properties damping="0.0" friction="0.0"/>
  </joint>

<!-- back right -->
  <link name="link_back_right_wheel">
    <inertial>
      <mass value="0.049"/>
      <origin rpy="0 -1.5707 -1.5707" xyz="0 0 0"/>
      <inertia ixx="1.755e-5" ixy="0" ixz="0" iyy="1.755e-5" iyz="0" izz="3.001e-5"/>
    </inertial>
    <collision name="link_back_right_wheel_collision">
      <origin rpy="0 -1.5707 -1.5707" xyz="0 0 0"/>
      <geometry>
        <cylinder length="0.025" radius="0.035"/>
      </geometry>
    </collision>
    <visual name="link_back_right_wheel_visual">
      <origin rpy="0 -1.5707 -1.5707" xyz="0 0 0"/>
      <geometry>
        <cylinder length="0.025" radius="0.035"/>
      </geometry>
    </visual>
  </link>
  
  <joint name="joint_back_right_wheel" type="continuous">
    <origin rpy="0 0 0" xyz="-0.125 -0.085  0"/>
    <child link="link_back_right_wheel"/>
    <parent link="link_chassis"/>
    <axis rpy="0 0 0" xyz="0 1 0"/>
    <limit effort="5" velocity="10"/>
    <joint_properties damping="0.0" friction="0.0"/>
  </joint>

<!-- back left -->
  <link name="link_back_left_wheel">
    <inertial>
      <mass value="0.049"/>
      <origin rpy="0 1.5707 1.5707" xyz="0 0 0"/>
      <inertia ixx="1.755e-5" ixy="0" ixz="0" iyy="1.755e-5" iyz="0" izz="3.001e-5"/>
    </inertial>
    <collision name="link_back_left_wheel_collision">
      <origin rpy="0 1.5707 1.5707" xyz="0 0 0"/>
      <geometry>
        <cylinder length="0.025" radius="0.035"/>
      </geometry>
    </collision>
    <visual name="link_back_left_wheel_visual">
      <origin rpy="0 1.5707 1.5707" xyz="0 0 0"/>
      <geometry>
        <cylinder length="0.025" radius="0.035"/>
      </geometry>
    </visual>
  </link>

  <joint name="joint_back_left_wheel" type="continuous">
    <origin rpy="0 0 0" xyz="-0.125 0.085 0.0"/>
    <child link="link_back_left_wheel"/>
    <parent link="link_chassis"/>
    <axis rpy="0 0 0" xyz="0 1 0"/>
    <limit effort="5" velocity="10"/>
    <joint_properties damping="0.0" friction="0.0"/>
  </joint>

  <!-- Camera link & joint -->
  <link name="camera_link">
	<inertial>
		<mass value = "1e-5"/>
		<origin xyz="0 0 0" rpy="0 0 0"/>
		<inertia ixx="1e-6" ixy="0" ixz="0" iyy="1e-6" iyz="0" izz="1e-6" />
	</inertial>
    <collision name = "camera_link_collision">
      	<origin xyz="0 0 0" rpy="0 0 0"/>
      	<geometry>
    		<box size="0.01 0.01 0.01"/>
      	</geometry>
    </collision>
    <visual>
      	<origin xyz="0 0 0" rpy="0 0 0"/>
      	<geometry>
    		<box size="0.01 0.01 0.01"/>
      	</geometry>
     </visual>
  </link>

  <joint name="camera_joint" type="fixed">
	<origin xyz="0.07 0 0.11" rpy="0 0.6266 0"/>
	<child link="camera_link"/>
	<parent link="link_chassis"/>
	<axis rpy = "0 0 0" xyz="0 1 0" />
  </joint>

<link name="imu_link">
<inertial>
<mass value = "1e-5"/>
<origin xyz="0 0 0" rpy="0 0 0"/>
<inertia ixx="1e-6" ixy="0" ixz="0" iyy="1e-6" iyz="0" izz="1e-6" />
</inertial>
<collision name = "imu_link_collision">
<origin xyz="0 0 0" rpy="0 0 0"/>
<geometry>
<box size="0.01 0.01 0.01"/>
</geometry>
</collision>
<visual name = "imu_link_visual">
<origin xyz="0 0 0" rpy="0 0 0"/>
<geometry>
<box size="0.01 0.01 0.01"/>
</geometry>
</visual>
</link>



<joint name="imu_joint" type="fixed">
<origin xyz="0.0 0 0.05" rpy="0 0 0"/>
<child link="imu_link"/>
<parent link="link_chassis"/>
<axis rpy = "0 0 0" xyz="0 1 0" />
</joint>

  <!-- IMU colour -->

<!--<gazebo reference="imu_link">
    <material>Gazebo/white</material>
  </gazebo>-->

<!--imu link and joint-->

<!--<link name="imu_link">
  <inertial>
    <mass value="1e-5"/>
    <origin rpy="0 0 0" xyz="0 0 0"/>
    <inertia ixx="1e-6" ixy="0" ixz="0" iyy="1e-6" iyz="0" izz="1e-6"/>
  </inertial>
  <visual>
    <origin rpy="0 0 0" xyz="0 0 0"/>
    <geometry>
      <box size="0.01 0.01 0.01"/>
    </geometry>
  </visual>
  <collision>
    <origin rpy="0 0 0" xyz="0 0 0"/>
    <geometry>
      <box size="0.01 0.01 0.01"/>
    </geometry>
  </collision>
</link>

<joint name="imu_joint" type="fixed">
    <origin xyz="0.0.085 0 0.05" rpy= "0 1 0"/>
    <parent link="link_chassis"/>
    <child link="imu_link"/>
    <axis rpy = "0 0 0" xyz="0 1 0"/>
  </joint>-->
 
  <!--imu plugin-->

  <!--<gazebo reference="imu_link">
    <sensor name="imu_sensor" type="imu">
      <always_on>true</always_on>
      <update_rate>100.0</update_rate>
      <visualize>true</visualize>
      <topic>imu_raw</topic>
      <plugin filename="libgazebo_ros_imu_sensor.so" name="imu_plugin">
        <topicName>imu/data</topicName>
        <bodyName>imu_body</bodyName>
        <updateRateHZ>10.0</updateRateHZ>
        <gaussianNoise>0.0</gaussianNoise>
        <xyzOffset>0 0 0</xyzOffset>
        <rpyOffset>0 0 0</rpyOffset>
        <frameName>imu_link</frameName>
        <initialOrientationAsReference>false</initialOrientationAsReference>
      </plugin>
    </sensor>
  </gazebo-->



  <transmission name = "joint_back_left_wheel_trans">
  	<type> transmission_interface/SimpleTransmission </type>
        <joint name = "joint_back_left_wheel">
        	<hardwareInterface> hardware_interface/VelocityJointInterface </hardwareInterface>
        </joint>
        <actuator name = "joint_back_left_wheel_motor">
                <hardwareInterface> hardware_interface/VelocityJointInterface </hardwareInterface>
  		<mechanicalReduction>1</mechanicalReduction>
	</actuator>
  </transmission>

  <transmission name = "joint_back_right_wheel_trans">
  	<type> transmission_interface/SimpleTransmission </type>
        <joint name = "joint_back_right_wheel">
        	<hardwareInterface> hardware_interface/VelocityJointInterface </hardwareInterface>
        </joint>
        <actuator name = "joint_back_right_wheel_motor">
                <hardwareInterface> hardware_interface/VelocityJointInterface </hardwareInterface>
  		<mechanicalReduction>1</mechanicalReduction>
	</actuator>
  </transmission>

  <transmission name = "joint_front_left_hinge_trans">
  	<type> transmission_interface/SimpleTransmission </type>
        <joint name = "joint_front_left_hinge">
        	<hardwareInterface> hardware_interface/PositionJointInterface </hardwareInterface>
        </joint>
        <actuator name = "joint_front_left_hinge_motor">
                <hardwareInterface> hardware_interface/PositionJointInterface </hardwareInterface>
  		<mechanicalReduction>1</mechanicalReduction>
	</actuator>
  </transmission>

  <transmission name = "joint_front_right_hinge_trans">
  	<type> transmission_interface/SimpleTransmission </type>
        <joint name = "joint_front_right_hinge">
        	<hardwareInterface> hardware_interface/PositionJointInterface </hardwareInterface>
        </joint>
        <actuator name = "joint_front_right_hinge_motor">
                <hardwareInterface> hardware_interface/PositionJointInterface </hardwareInterface>
  		<mechanicalReduction>1</mechanicalReduction>
	</actuator>
  </transmission>


<gazebo>
  <plugin name="gazebo_ros_control" filename="libgazebo_ros_control.so">
    <robotNamespace>/rover</robotNamespace>
  </plugin>
</gazebo>
</robot>

